Exception in Tkinter callback
Traceback (most recent call last):
  File "C:\Program Files\Python39\lib\tkinter\__init__.py", line 1892, in __call__
    return self.func(*args)
  File "main.py", line 57, in <lambda>
    bt_go = tkinter.Button(fenetre, text="Générer", command=lambda: go(
  File "main.py", line 23, in go
    donnees = recuperer(entree_in)
  File "C:\Users\Xavier\trav\tableurs\290521\input.py", line 104, in recuperer
    return convertir(lire_donnees(nom_fichier))
  File "C:\Users\Xavier\trav\tableurs\290521\input.py", line 47, in convertir
    for index, ligne in enumerate(donnees):
  File "C:\Users\Xavier\trav\tableurs\290521\input.py", line 22, in lire_donnees
    with open(nom_fichier, encoding='UTF8') as fichier:
TypeError: expected str, bytes or os.PathLike object, not OpenFileEntry
